<mujoco model="inverted_pendulum">
    <compiler angle="degree" coordinate="local"/>
    <option timestep="0.01"/>

    <worldbody>
        <body name="cart" pos="0 0 0">
            <joint name="slide" type="slide" axis="1 0 0"/>
            <geom name="track" type="plane" size="10 10 0.1" pos="0 0 0"/>
            <body name="pole" pos="0 0 0">
                <joint name="hinge" type="hinge" axis="0 1 0"/>
                <geom name="pole_geom" type="capsule" fromto="0 0 0 0 0 1" size="0.05"/>
            </body>
        </body>
    </worldbody>

    <actuator>
        <motor joint="slide" ctrlrange="-10 10" ctrllimited="true"/>
    </actuator>
</mujoco>
